Workbook

Sheet About
A1: Defense backlog forecast
A2: Question: does backlog at quarter end forecast the next quarters' revenue better than last year's revenue does?
A4: Method
A5: 1. Backlog is XBRL remaining performance obligations (RPO), first reported in each 10-Q or 10-K.
A6: 2. Revenue is the first-reported three-month figure; Q4 is the full year less nine months.
A7: 3. Backlog model: backlog times the average conversion rate seen one and two years earlier.
A8: 4. Baselines: same quarter last year (H1) or trailing four quarters (H4), each with and without drift.
A9: 5. Every forecast uses only figures known at its origin quarter; APE scores it against reported revenue.
A11: Colour key
A12: Blue figures are typed inputs from SEC filings. Black figures are formulas.
A13: Dollars are in $M (USD / 1,000,000). Ratios have two decimals; percents one.
A15: Source: SEC EDGAR XBRL, first reported, as of 2026-10-13. https://data.sec.gov/api/xbrl/companyfacts/
... A17: Built by Rishabb Shankar, https://rshankar.dev

Sheet Data
A1: ticker | B1: quarter | C1: period_end | D1: backlog_usd | E1: backlog_accn | F1: backlog_filed | G1: revenue_usd | H1: revenue_method | I1: revenue_tag | J1: revenue_accn | K1: revenue_filed
A2: HII | B2: 2018Q1 | C2: 2018-03-31 | D2: 22100000000 | E2: 0001501585-18-000010 | F2: 2018-05-03 | G2: 1874000000 | H2: reported_3m | I2: Revenues | J2: 0001501585-19-000005 | K2: 2019-02-14
A3: HII | B3: 2018Q2 | C3: 2018-06-30 | D3: 21200000000 | E3: 0001501585-18-000027 | F3: 2018-08-02 | G3: 2020000000 | H3: reported_3m | I3: Revenues | J3: 0001501585-19-000005 | K3: 2019-02-14
A4: HII | B4: 2018Q3 | C4: 2018-09-30 | D4: 21900000000 | E4: 0001501585-18-000035 | F4: 2018-11-08 | G4: 2083000000 | H4: reported_3m | I4: Revenues | J4: 0001501585-18-000035 | K4: 2018-11-08
A5: HII | B5: 2018Q4 | C5: 2018-12-31 | D5: 23000000000 | E5: 0001501585-19-000005 | F5: 2019-02-14 | G5: 2199000000 | H5: reported_3m | I5: Revenues | J5: 0001501585-19-000005 | K5: 2019-02-14
A6: HII | B6: 2019Q1 | C6: 2019-03-31 | D6: 40600000000 | E6: 0001501585-19-000011 | F6: 2019-05-02 | G6: 2080000000 | H6: reported_3m | I6: Revenues | J6: 0001501585-19-000011 | K6: 2019-05-02
A7: HII | B7: 2019Q2 | C7: 2019-06-30 | D7: 39400000000 | E7: 0001501585-19-000021 | F7: 2019-08-01 | G7: 2188000000 | H7: reported_3m | I7: Revenues | J7: 0001501585-19-000021 | K7: 2019-08-01
A8: HII | B8: 2019Q3 | C8: 2019-09-30 | D8: 39200000000 | E8: 0001501585-19-000026 | F8: 2019-11-07 | G8: 2219000000 | H8: reported_3m | I8: Revenues | J8: 0001501585-19-000026 | K8: 2019-11-07
A9: HII | B9: 2019Q4 | C9: 2019-12-31 | D9: 46500000000 | E9: 0001501585-20-000011 | F9: 2020-02-13 | G9: 2412000000 | H9: reported_3m | I9: Revenues | J9: 0001501585-20-000011 | K9: 2020-02-13
A10: HII | B10: 2020Q1 | C10: 2020-03-31 | D10: 45200000000 | E10: 0001501585-20-000019 | F10: 2020-05-07 | G10: 2263000000 | H10: reported_3m | I10: Revenues | J10: 0001501585-20-000019 | K10: 2020-05-07
A11: HII | B11: 2020Q2 | C11: 2020-06-30 | D11: 46100000000 | E11: 0001501585-20-000035 | F11: 2020-08-06 | G11: 2027000000 | H11: reported_3m | I11: Revenues | J11: 0001501585-20-000035 | K11: 2020-08-06
A12: HII | B12: 2020Q3 | C12: 2020-09-30 | D12: 45300000000 | E12: 0001501585-20-000042 | F12: 2020-11-05 | G12: 2314000000 | H12: reported_3m | I12: Revenues | J12: 0001501585-20-000042 | K12: 2020-11-05
A13: HII | B13: 2020Q4 | C13: 2020-12-31 | D13: 46000000000 | E13: 0001501585-21-000008 | F13: 2021-02-11 | G13: 2757000000 | H13: reported_3m | I13: Revenues | J13: 0001501585-21-000008 | K13: 2021-02-11
... A35: HII | B35: 2026Q2 | C35: 2026-06-30 | D35: 57300000000 | E35: 0001501585-26-000047 | F35: 2026-07-30 | G35: 3418000000 | H35: reported_3m | I35: Revenues | J35: 0001501585-26-000047 | K35: 2026-07-30
A36: LHX | B36: 2020Q1 | G36: 4626000000 | H36: reported_3m | I36: RevenueFromContractWithCustomerExcludingAssessedTax | J36: 0000202058-20-000040 | K36: 2020-05-07
A37: LHX | B37: 2020Q2 | G37: 4445000000 | H37: reported_3m | I37: RevenueFromContractWithCustomerExcludingAssessedTax | J37: 0000202058-20-000053 | K37: 2020-08-04
A38: LHX | B38: 2020Q3 | G38: 4463000000 | H38: reported_3m | I38: RevenueFromContractWithCustomerExcludingAssessedTax | J38: 0000202058-20-000063 | K38: 2020-11-02
A39: LHX | B39: 2020Q4 | C39: 2021-01-01 | D39: 21700000000 | E39: 0000202058-21-000008 | F39: 2021-03-01 | G39: 4660000000 | H39: fy_minus_9m | I39: RevenueFromContractWithCustomerExcludingAssessedTax | J39: 0000202058-21-000008 | K39: 2021-03-01
A40: LHX | B40: 2021Q1 | G40: 4567000000 | H40: reported_3m | I40: RevenueFromContractWithCustomerExcludingAssessedTax | J40: 0000202058-21-000020 | K40: 2021-05-03
A41: LHX | B41: 2021Q2 | G41: 4668000000 | H41: reported_3m | I41: RevenueFromContractWithCustomerExcludingAssessedTax | J41: 0000202058-21-000046 | K41: 2021-08-04
A42: LHX | B42: 2021Q3 | G42: 4229000000 | H42: reported_3m | I42: RevenueFromContractWithCustomerExcludingAssessedTax | J42: 0000202058-21-000054 | K42: 2021-10-29
A43: LHX | B43: 2021Q4 | C43: 2021-12-31 | D43: 21100000000 | E43: 0000202058-22-000029 | F43: 2022-04-29 | G43: 4350000000 | H43: fy_minus_9m | I43: RevenueFromContractWithCustomerExcludingAssessedTax | J43: 0000202058-22-000015 | K43: 2022-02-25
A44: LHX | B44: 2022Q1 | C44: 2022-04-01 | D44: 21100000000 | E44: 0000202058-22-000029 | F44: 2022-04-29 | G44: 4103000000 | H44: reported_3m | I44: RevenueFromContractWithCustomerExcludingAssessedTax | J44: 0000202058-22-000029 | K44: 2022-04-29
A45: LHX | B45: 2022Q2 | C45: 2022-07-01 | D45: 19900000000 | E45: 0000202058-22-000051 | F45: 2022-07-29 | G45: 4135000000 | H45: reported_3m | I45: RevenueFromContractWithCustomerExcludingAssessedTax | J45: 0000202058-22-000051 | K45: 2022-07-29
A46: LHX | B46: 2022Q3 | C46: 2022-09-30 | D46: 21400000000 | E46: 0000202058-22-000063 | F46: 2022-10-31 | G46: 4246000000 | H46: reported_3m | I46: RevenueFromContractWithCustomerExcludingAssessedTax | J46: 0000202058-22-000063 | K46: 2022-10-31
A47: LHX | B47: 2022Q4 | C47: 2022-12-30 | D47: 22300000000 | E47: 0000202058-23-000014 | F47: 2023-02-24 | G47: 4578000000 | H47: fy_minus_9m | I47: RevenueFromContractWithCustomerExcludingAssessedTax | J47: 0000202058-23-000014 | K47: 2023-02-24
A48: LHX | B48: 2023Q1 | C48: 2023-03-31 | D48: 24500000000 | E48: 0000202058-23-000028 | F48: 2023-04-28 | G48: 4471000000 | H48: reported_3m | I48: RevenueFromContractWithCustomerExcludingAssessedTax | J48: 0000202058-23-000028 | K48: 2023-04-28
A49: LHX | B49: 2023Q2 | C49: 2023-06-30 | D49: 24900000000 | E49: 0000202058-23-000047 | F49: 2023-07-26 | G49: 4693000000 | H49: reported_3m | I49: RevenueFromContractWithCustomerExcludingAssessedTax | J49: 0000202058-23-000047 | K49: 2023-07-26
A50: LHX | B50: 2023Q3 | C50: 2023-09-29 | D50: 31800000000 | E50: 0000202058-23-000057 | F50: 2023-10-27 | G50: 4915000000 | H50: reported_3m | I50: RevenueFromContractWithCustomerExcludingAssessedTax | J50: 0000202058-23-000057 | K50: 2023-10-27
A51: LHX | B51: 2023Q4 | C51: 2023-12-29 | D51: 32700000000 | E51: 0000202058-24-000029 | F51: 2024-02-20 | G51: 5340000000 | H51: fy_minus_9m | I51: RevenueFromContractWithCustomerExcludingAssessedTax | J51: 0000202058-24-000029 | K51: 2024-02-20
A52: LHX | B52: 2024Q1 | C52: 2024-03-29 | D52: 32100000000 | E52: 0000202058-24-000103 | F52: 2024-04-26 | G52: 5211000000 | H52: reported_3m | I52: RevenueFromContractWithCustomerExcludingAssessedTax | J52: 0000202058-24-000103 | K52: 2024-04-26
A53: LHX | B53: 2024Q2 | C53: 2024-06-28 | D53: 31700000000 | E53: 0000202058-24-000140 | F53: 2024-07-26 | G53: 5299000000 | H53: reported_3m | I53: RevenueFromContractWithCustomerExcludingAssessedTax | J53: 0000202058-24-000140 | K53: 2024-07-26
A54: LHX | B54: 2024Q3 | C54: 2024-09-27 | D54: 33800000000 | E54: 0000202058-24-000168 | F54: 2024-10-25 | G54: 5292000000 | H54: reported_3m | I54: RevenueFromContractWithCustomerExcludingAssessedTax | J54: 0000202058-24-000168 | K54: 2024-10-25
... A152: RTX | B152: 2026Q2 | C152: 2026-06-30 | D152: 289000000000 | E152: 0000101829-26-000027 | F152: 2026-07-23 | G152: 24708000000 | H152: reported_3m | I152: RevenueFromContractWithCustomerExcludingAssessedTax | J152: 0000101829-26-000027 | K152: 2026-07-23

Sheet HII
A1: Quarter | B1: 2018Q1 | C1: 2018Q2 | D1: 2018Q3 | E1: 2018Q4 | F1: 2019Q1 | G1: 2019Q2 | H1: 2019Q3 | I1: 2019Q4 | J1: 2020Q1 | K1: 2020Q2 | L1: 2020Q3 | M1: 2020Q4 | N1: 2021Q1 | O1: 2021Q2 | P1: 2021Q3 | Q1: 2021Q4 | R1: 2022Q1 | S1: 2022Q2 | T1: 2022Q3 | U1: 2022Q4 | V1: 2023Q1 | W1: 2023Q2 | X1: 2023Q3 | Y1: 2023Q4 | Z1: 2024Q1 | AA1: 2024Q2 | AB1: 2024Q3 | AC1: 2024Q4 | AD1: 2025Q1 | AE1: 2025Q2 | AF1: 2025Q3 | AG1: 2025Q4 | AH1: 2026Q1 | AI1: 2026Q2
A2: Backlog (RPO) | B2: 22100 | C2: 21200 | D2: 21900 | E2: 23000 | F2: 40600 | G2: 39400 | H2: 39200 | I2: 46500 | J2: 45200 | K2: 46100 | L2: 45300 | M2: 46000 | N2: 48800 | O2: 47700 | P2: 50100 | Q2: 48500 | R2: 47900 | S2: 47200 | T2: 46700 | U2: 47100 | V2: 47000 | W2: 46900 | X2: 49400 | Y2: 48100 | Z2: 48400 | AA2: 48500 | AB2: 49400 | AC2: 48700 | AD2: 48000 | AE2: 56900 | AF2: 55700 | AG2: 53100 | AH2: 54000 | AI2: 57300
A3: Revenue | B3: 1874 | C3: 2020 | D3: 2083 | E3: 2199 | F3: 2080 | G3: 2188 | H3: 2219 | I3: 2412 | J3: 2263 | K3: 2027 | L3: 2314 | M3: 2757 | N3: 2278 | O3: 2231 | P3: 2338 | Q3: 2677 | R3: 2576 | S3: 2662 | T3: 2626 | U3: 2812 | V3: 2674 | W3: 2787 | X3: 2816 | Y3: 3177 | Z3: 2805 | AA3: 2977 | AB3: 2749 | AC3: 3004 | AD3: 2734 | AE3: 3082 | AF3: 3192 | AG3: 3476 | AH3: 3099 | AI3: 3418
A4: Implied bookings | C4: =C2-B2+C3 | D4: =D2-C2+D3 | E4: =E2-D2+E3 | F4: =F2-E2+F3 | G4: =G2-F2+G3 | H4: =H2-G2+H3 | I4: =I2-H2+I3 | J4: =J2-I2+J3 | ... AI4: =AI2-AH2+AI3
A5: Book-to-bill | C5: =C4/C3 | D5: =D4/D3 | E5: =E4/E3 | F5: =F4/F3 | G5: =G4/G3 | H5: =H4/H3 | I5: =I4/I3 | J5: =J4/J3 | ... AI5: =AI4/AI3
A6: Conversion 1Q | B6: =C3/B2 | C6: =D3/C2 | D6: =E3/D2 | E6: =F3/E2 | F6: =G3/F2 | G6: =H3/G2 | H6: =I3/H2 | I6: =J3/I2 | ... AH6: =AI3/AH2
A7: Conversion 4Q | B7: =SUM(C3:F3)/B2 | C7: =SUM(D3:G3)/C2 | D7: =SUM(E3:H3)/D2 | E7: =SUM(F3:I3)/E2 | F7: =SUM(G3:J3)/F2 | G7: =SUM(H3:K3)/G2 | H7: =SUM(I3:L3)/H2 | I7: =SUM(J3:M3)/I2 | ... AE7: =SUM(AF3:AI3)/AE2
A8: H1 backlog forecast | K8: =J2*AVERAGE(F6,B6) | L8: =K2*AVERAGE(G6,C6) | M8: =L2*AVERAGE(H6,D6) | N8: =M2*AVERAGE(I6,E6) | O8: =N2*AVERAGE(J6,F6) | P8: =O2*AVERAGE(K6,G6) | Q8: =P2*AVERAGE(L6,H6) | R8: =Q2*AVERAGE(M6,I6) | ... AI8: =AH2*AVERAGE(AD6,Z6)
A9: H1 seasonal naive | K9: =G3 | L9: =H3 | M9: =I3 | N9: =J3 | O9: =K3 | P9: =L3 | Q9: =M3 | R9: =N3 | ... AI9: =AE3
A10: H1 naive with drift | K10: =G3*SUM(G3:J3)/SUM(C3:F3) | L10: =H3*SUM(H3:K3)/SUM(D3:G3) | M10: =I3*SUM(I3:L3)/SUM(E3:H3) | N10: =J3*SUM(J3:M3)/SUM(F3:I3) | O10: =K3*SUM(K3:N3)/SUM(G3:J3) | P10: =L3*SUM(L3:O3)/SUM(H3:K3) | Q10: =M3*SUM(M3:P3)/SUM(I3:L3) | R10: =N3*SUM(N3:Q3)/SUM(J3:M3) | ... AI10: =AE3*SUM(AE3:AH3)/SUM(AA3:AD3)
A11: H1 backlog APE % | K11: =ABS(K3-K8)/K3*100 | L11: =ABS(L3-L8)/L3*100 | M11: =ABS(M3-M8)/M3*100 | N11: =ABS(N3-N8)/N3*100 | O11: =ABS(O3-O8)/O3*100 | P11: =ABS(P3-P8)/P3*100 | Q11: =ABS(Q3-Q8)/Q3*100 | R11: =ABS(R3-R8)/R3*100 | ... AI11: =ABS(AI3-AI8)/AI3*100
A12: H1 seasonal naive APE % | K12: =ABS(K3-K9)/K3*100 | L12: =ABS(L3-L9)/L3*100 | M12: =ABS(M3-M9)/M3*100 | N12: =ABS(N3-N9)/N3*100 | O12: =ABS(O3-O9)/O3*100 | P12: =ABS(P3-P9)/P3*100 | Q12: =ABS(Q3-Q9)/Q3*100 | R12: =ABS(R3-R9)/R3*100 | ... AI12: =ABS(AI3-AI9)/AI3*100
A13: H1 naive with drift APE % | K13: =ABS(K3-K10)/K3*100 | L13: =ABS(L3-L10)/L3*100 | M13: =ABS(M3-M10)/M3*100 | N13: =ABS(N3-N10)/N3*100 | O13: =ABS(O3-O10)/O3*100 | P13: =ABS(P3-P10)/P3*100 | Q13: =ABS(Q3-Q10)/Q3*100 | R13: =ABS(R3-R10)/R3*100 | ... AI13: =ABS(AI3-AI10)/AI3*100
A14: H4 actual | J14: =SUM(K3:N3) | K14: =SUM(L3:O3) | L14: =SUM(M3:P3) | M14: =SUM(N3:Q3) | N14: =SUM(O3:R3) | O14: =SUM(P3:S3) | P14: =SUM(Q3:T3) | Q14: =SUM(R3:U3) | ... AE14: =SUM(AF3:AI3)
A15: H4 backlog forecast | J15: =J2*AVERAGE(C7:F7) | K15: =K2*AVERAGE(D7:G7) | L15: =L2*AVERAGE(E7:H7) | M15: =M2*AVERAGE(F7:I7) | N15: =N2*AVERAGE(G7:J7) | O15: =O2*AVERAGE(H7:K7) | P15: =P2*AVERAGE(I7:L7) | Q15: =Q2*AVERAGE(J7:M7) | ... AE15: =AE2*AVERAGE(X7:AA7)
A16: H4 trailing 4Q | J16: =SUM(G3:J3) | K16: =SUM(H3:K3) | L16: =SUM(I3:L3) | M16: =SUM(J3:M3) | N16: =SUM(K3:N3) | O16: =SUM(L3:O3) | P16: =SUM(M3:P3) | Q16: =SUM(N3:Q3) | ... AE16: =SUM(AB3:AE3)
A17: H4 trailing 4Q with drift | J17: =SUM(G3:J3)^2/SUM(C3:F3) | K17: =SUM(H3:K3)^2/SUM(D3:G3) | L17: =SUM(I3:L3)^2/SUM(E3:H3) | M17: =SUM(J3:M3)^2/SUM(F3:I3) | N17: =SUM(K3:N3)^2/SUM(G3:J3) | O17: =SUM(L3:O3)^2/SUM(H3:K3) | P17: =SUM(M3:P3)^2/SUM(I3:L3) | Q17: =SUM(N3:Q3)^2/SUM(J3:M3) | ... AE17: =SUM(AB3:AE3)^2/SUM(X3:AA3)
A18: H4 backlog APE % | J18: =ABS(J14-J15)/J14*100 | K18: =ABS(K14-K15)/K14*100 | L18: =ABS(L14-L15)/L14*100 | M18: =ABS(M14-M15)/M14*100 | N18: =ABS(N14-N15)/N14*100 | O18: =ABS(O14-O15)/O14*100 | P18: =ABS(P14-P15)/P14*100 | Q18: =ABS(Q14-Q15)/Q14*100 | ... AE18: =ABS(AE14-AE15)/AE14*100
A19: H4 trailing 4Q APE % | J19: =ABS(J14-J16)/J14*100 | K19: =ABS(K14-K16)/K14*100 | L19: =ABS(L14-L16)/L14*100 | M19: =ABS(M14-M16)/M14*100 | N19: =ABS(N14-N16)/N14*100 | O19: =ABS(O14-O16)/O14*100 | P19: =ABS(P14-P16)/P14*100 | Q19: =ABS(Q14-Q16)/Q14*100 | ... AE19: =ABS(AE14-AE16)/AE14*100
A20: H4 trailing 4Q with drift APE % | J20: =ABS(J14-J17)/J14*100 | K20: =ABS(K14-K17)/K14*100 | L20: =ABS(L14-L17)/L14*100 | M20: =ABS(M14-M17)/M14*100 | N20: =ABS(N14-N17)/N14*100 | O20: =ABS(O14-O17)/O14*100 | P20: =ABS(P14-P17)/P14*100 | Q20: =ABS(Q14-Q17)/Q14*100 | ... AE20: =ABS(AE14-AE17)/AE14*100

Sheet LHX
A1: Quarter | B1: 2020Q1 | C1: 2020Q2 | D1: 2020Q3 | E1: 2020Q4 | F1: 2021Q1 | G1: 2021Q2 | H1: 2021Q3 | I1: 2021Q4 | J1: 2022Q1 | K1: 2022Q2 | L1: 2022Q3 | M1: 2022Q4 | N1: 2023Q1 | O1: 2023Q2 | P1: 2023Q3 | Q1: 2023Q4 | R1: 2024Q1 | S1: 2024Q2 | T1: 2024Q3 | U1: 2024Q4 | V1: 2025Q1 | W1: 2025Q2 | X1: 2025Q3 | Y1: 2025Q4 | Z1: 2026Q1 | AA1: 2026Q2
A2: Backlog (RPO) | E2: 21700 | I2: 21100 | J2: 21100 | K2: 19900 | L2: 21400 | M2: 22300 | N2: 24500 | O2: 24900 | P2: 31800 | Q2: 32700 | R2: 32100 | S2: 31700 | T2: 33800 | U2: 34200 | V2: 33200 | W2: 35400 | X2: 36300 | Y2: 38700 | Z2: 40700 | AA2: 42000
A3: Revenue | B3: 4626 | C3: 4445 | D3: 4463 | E3: 4660 | F3: 4567 | G3: 4668 | H3: 4229 | I3: 4350 | J3: 4103 | K3: 4135 | L3: 4246 | M3: 4578 | N3: 4471 | O3: 4693 | P3: 4915 | Q3: 5340 | R3: 5211 | S3: 5299 | T3: 5292 | U3: 5523 | V3: 5132 | W3: 5426 | X3: 5659 | Y3: 5648 | Z3: 5744 | AA3: 5881
A4: Implied bookings | J4: =J2-I2+J3 | K4: =K2-J2+K3 | L4: =L2-K2+L3 | M4: =M2-L2+M3 | N4: =N2-M2+N3 | O4: =O2-N2+O3 | P4: =P2-O2+P3 | Q4: =Q2-P2+Q3 | ... AA4: =AA2-Z2+AA3
A5: Book-to-bill | J5: =J4/J3 | K5: =K4/K3 | L5: =L4/L3 | M5: =M4/M3 | N5: =N4/N3 | O5: =O4/O3 | P5: =P4/P3 | Q5: =Q4/Q3 | ... AA5: =AA4/AA3
A6: Conversion 1Q | E6: =F3/E2 | I6: =J3/I2 | J6: =K3/J2 | K6: =L3/K2 | L6: =M3/L2 | M6: =N3/M2 | N6: =O3/N2 | O6: =P3/O2 | P6: =Q3/P2 | ... Z6: =AA3/Z2
A7: Conversion 4Q | E7: =SUM(F3:I3)/E2 | I7: =SUM(J3:M3)/I2 | J7: =SUM(K3:N3)/J2 | K7: =SUM(L3:O3)/K2 | L7: =SUM(M3:P3)/L2 | M7: =SUM(N3:Q3)/M2 | N7: =SUM(O3:R3)/N2 | O7: =SUM(P3:S3)/O2 | P7: =SUM(Q3:T3)/P2 | ... W7: =SUM(X3:AA3)/W2
A8: H1 backlog forecast | N8: =M2*AVERAGE(I6,E6) | R8: =Q2*AVERAGE(M6,I6) | S8: =R2*AVERAGE(N6,J6) | T8: =S2*AVERAGE(O6,K6) | U8: =T2*AVERAGE(P6,L6) | V8: =U2*AVERAGE(Q6,M6) | W8: =V2*AVERAGE(R6,N6) | X8: =W2*AVERAGE(S6,O6) | Y8: =X2*AVERAGE(T6,P6) | ... AA8: =Z2*AVERAGE(V6,R6)
A9: H1 seasonal naive | K9: =G3 | L9: =H3 | M9: =I3 | N9: =J3 | O9: =K3 | P9: =L3 | Q9: =M3 | R9: =N3 | ... AA9: =W3
A10: H1 naive with drift | K10: =G3*SUM(G3:J3)/SUM(C3:F3) | L10: =H3*SUM(H3:K3)/SUM(D3:G3) | M10: =I3*SUM(I3:L3)/SUM(E3:H3) | N10: =J3*SUM(J3:M3)/SUM(F3:I3) | O10: =K3*SUM(K3:N3)/SUM(G3:J3) | P10: =L3*SUM(L3:O3)/SUM(H3:K3) | Q10: =M3*SUM(M3:P3)/SUM(I3:L3) | R10: =N3*SUM(N3:Q3)/SUM(J3:M3) | ... AA10: =W3*SUM(W3:Z3)/SUM(S3:V3)
A11: H1 backlog APE % | N11: =ABS(N3-N8)/N3*100 | R11: =ABS(R3-R8)/R3*100 | S11: =ABS(S3-S8)/S3*100 | T11: =ABS(T3-T8)/T3*100 | U11: =ABS(U3-U8)/U3*100 | V11: =ABS(V3-V8)/V3*100 | W11: =ABS(W3-W8)/W3*100 | X11: =ABS(X3-X8)/X3*100 | Y11: =ABS(Y3-Y8)/Y3*100 | ... AA11: =ABS(AA3-AA8)/AA3*100
A12: H1 seasonal naive APE % | K12: =ABS(K3-K9)/K3*100 | L12: =ABS(L3-L9)/L3*100 | M12: =ABS(M3-M9)/M3*100 | N12: =ABS(N3-N9)/N3*100 | O12: =ABS(O3-O9)/O3*100 | P12: =ABS(P3-P9)/P3*100 | Q12: =ABS(Q3-Q9)/Q3*100 | R12: =ABS(R3-R9)/R3*100 | ... AA12: =ABS(AA3-AA9)/AA3*100
A13: H1 naive with drift APE % | K13: =ABS(K3-K10)/K3*100 | L13: =ABS(L3-L10)/L3*100 | M13: =ABS(M3-M10)/M3*100 | N13: =ABS(N3-N10)/N3*100 | O13: =ABS(O3-O10)/O3*100 | P13: =ABS(P3-P10)/P3*100 | Q13: =ABS(Q3-Q10)/Q3*100 | R13: =ABS(R3-R10)/R3*100 | ... AA13: =ABS(AA3-AA10)/AA3*100
A14: H4 actual | J14: =SUM(K3:N3) | K14: =SUM(L3:O3) | L14: =SUM(M3:P3) | M14: =SUM(N3:Q3) | N14: =SUM(O3:R3) | O14: =SUM(P3:S3) | P14: =SUM(Q3:T3) | Q14: =SUM(R3:U3) | ... W14: =SUM(X3:AA3)
A15: H4 backlog forecast | P15: =P2*AVERAGE(I7:L7) | Q15: =Q2*AVERAGE(J7:M7) | R15: =R2*AVERAGE(K7:N7) | S15: =S2*AVERAGE(L7:O7) | T15: =T2*AVERAGE(M7:P7) | U15: =U2*AVERAGE(N7:Q7) | V15: =V2*AVERAGE(O7:R7) | W15: =W2*AVERAGE(P7:S7)
A16: H4 trailing 4Q | J16: =SUM(G3:J3) | K16: =SUM(H3:K3) | L16: =SUM(I3:L3) | M16: =SUM(J3:M3) | N16: =SUM(K3:N3) | O16: =SUM(L3:O3) | P16: =SUM(M3:P3) | Q16: =SUM(N3:Q3) | ... W16: =SUM(T3:W3)
A17: H4 trailing 4Q with drift | J17: =SUM(G3:J3)^2/SUM(C3:F3) | K17: =SUM(H3:K3)^2/SUM(D3:G3) | L17: =SUM(I3:L3)^2/SUM(E3:H3) | M17: =SUM(J3:M3)^2/SUM(F3:I3) | N17: =SUM(K3:N3)^2/SUM(G3:J3) | O17: =SUM(L3:O3)^2/SUM(H3:K3) | P17: =SUM(M3:P3)^2/SUM(I3:L3) | Q17: =SUM(N3:Q3)^2/SUM(J3:M3) | ... W17: =SUM(T3:W3)^2/SUM(P3:S3)
A18: H4 backlog APE % | P18: =ABS(P14-P15)/P14*100 | Q18: =ABS(Q14-Q15)/Q14*100 | R18: =ABS(R14-R15)/R14*100 | S18: =ABS(S14-S15)/S14*100 | T18: =ABS(T14-T15)/T14*100 | U18: =ABS(U14-U15)/U14*100 | V18: =ABS(V14-V15)/V14*100 | W18: =ABS(W14-W15)/W14*100
A19: H4 trailing 4Q APE % | J19: =ABS(J14-J16)/J14*100 | K19: =ABS(K14-K16)/K14*100 | L19: =ABS(L14-L16)/L14*100 | M19: =ABS(M14-M16)/M14*100 | N19: =ABS(N14-N16)/N14*100 | O19: =ABS(O14-O16)/O14*100 | P19: =ABS(P14-P16)/P14*100 | Q19: =ABS(Q14-Q16)/Q14*100 | ... W19: =ABS(W14-W16)/W14*100
A20: H4 trailing 4Q with drift APE % | J20: =ABS(J14-J17)/J14*100 | K20: =ABS(K14-K17)/K14*100 | L20: =ABS(L14-L17)/L14*100 | M20: =ABS(M14-M17)/M14*100 | N20: =ABS(N14-N17)/N14*100 | O20: =ABS(O14-O17)/O14*100 | P20: =ABS(P14-P17)/P14*100 | Q20: =ABS(Q14-Q17)/Q14*100 | ... W20: =ABS(W14-W17)/W14*100

Sheet LMT
A1: Quarter | B1: 2018Q1 | C1: 2018Q2 | D1: 2018Q3 | E1: 2018Q4 | F1: 2019Q1 | G1: 2019Q2 | H1: 2019Q3 | I1: 2019Q4 | J1: 2020Q1 | K1: 2020Q2 | L1: 2020Q3 | M1: 2020Q4 | N1: 2021Q1 | O1: 2021Q2 | P1: 2021Q3 | Q1: 2021Q4 | R1: 2022Q1 | S1: 2022Q2 | T1: 2022Q3 | U1: 2022Q4 | V1: 2023Q1 | W1: 2023Q2 | X1: 2023Q3 | Y1: 2023Q4 | Z1: 2024Q1 | AA1: 2024Q2 | AB1: 2024Q3 | AC1: 2024Q4 | AD1: 2025Q1 | AE1: 2025Q2 | AF1: 2025Q3 | AG1: 2025Q4 | AH1: 2026Q1 | AI1: 2026Q2
A2: Backlog (RPO) | B2: 104800 | C2: 105000 | D2: 109000 | E2: 130500 | F2: 133500 | G2: 136700 | H2: 137400 | I2: 144000 | J2: 144100 | K2: 150300 | L2: 150400 | M2: 147100 | N2: 147400 | O2: 141700 | P2: 134800 | Q2: 135400 | R2: 134200 | S2: 134600 | T2: 139700 | U2: 150000 | V2: 145100 | W2: 158000 | X2: 156000 | Y2: 160600 | Z2: 159400 | AA2: 158300 | AB2: 165700 | AC2: 176000 | AD2: 173000 | AE2: 166500 | AF2: 179100 | AG2: 193600 | AH2: 186400 | AI2: 230400
A3: Revenue | B3: 11635 | C3: 13398 | D3: 14318 | E3: 14411 | F3: 14336 | G3: 14427 | H3: 15171 | I3: 15878 | J3: 15651 | K3: 16220 | L3: 16495 | M3: 17032 | N3: 16258 | O3: 17029 | P3: 16028 | Q3: 17729 | R3: 14964 | S3: 15446 | T3: 16583 | U3: 18991 | V3: 15126 | W3: 16693 | X3: 16878 | Y3: 18874 | Z3: 17195 | AA3: 18122 | AB3: 17104 | AC3: 18622 | AD3: 17963 | AE3: 18155 | AF3: 18609 | AG3: 20321 | AH3: 18021 | AI3: 20063
A4: Implied bookings | C4: =C2-B2+C3 | D4: =D2-C2+D3 | E4: =E2-D2+E3 | F4: =F2-E2+F3 | G4: =G2-F2+G3 | H4: =H2-G2+H3 | I4: =I2-H2+I3 | J4: =J2-I2+J3 | ... AI4: =AI2-AH2+AI3
A5: Book-to-bill | C5: =C4/C3 | D5: =D4/D3 | E5: =E4/E3 | F5: =F4/F3 | G5: =G4/G3 | H5: =H4/H3 | I5: =I4/I3 | J5: =J4/J3 | ... AI5: =AI4/AI3
A6: Conversion 1Q | B6: =C3/B2 | C6: =D3/C2 | D6: =E3/D2 | E6: =F3/E2 | F6: =G3/F2 | G6: =H3/G2 | H6: =I3/H2 | I6: =J3/I2 | ... AH6: =AI3/AH2
A7: Conversion 4Q | B7: =SUM(C3:F3)/B2 | C7: =SUM(D3:G3)/C2 | D7: =SUM(E3:H3)/D2 | E7: =SUM(F3:I3)/E2 | F7: =SUM(G3:J3)/F2 | G7: =SUM(H3:K3)/G2 | H7: =SUM(I3:L3)/H2 | I7: =SUM(J3:M3)/I2 | ... AE7: =SUM(AF3:AI3)/AE2
A8: H1 backlog forecast | K8: =J2*AVERAGE(F6,B6) | L8: =K2*AVERAGE(G6,C6) | M8: =L2*AVERAGE(H6,D6) | N8: =M2*AVERAGE(I6,E6) | O8: =N2*AVERAGE(J6,F6) | P8: =O2*AVERAGE(K6,G6) | Q8: =P2*AVERAGE(L6,H6) | R8: =Q2*AVERAGE(M6,I6) | ... AI8: =AH2*AVERAGE(AD6,Z6)
A9: H1 seasonal naive | K9: =G3 | L9: =H3 | M9: =I3 | N9: =J3 | O9: =K3 | P9: =L3 | Q9: =M3 | R9: =N3 | ... AI9: =AE3
A10: H1 naive with drift | K10: =G3*SUM(G3:J3)/SUM(C3:F3) | L10: =H3*SUM(H3:K3)/SUM(D3:G3) | M10: =I3*SUM(I3:L3)/SUM(E3:H3) | N10: =J3*SUM(J3:M3)/SUM(F3:I3) | O10: =K3*SUM(K3:N3)/SUM(G3:J3) | P10: =L3*SUM(L3:O3)/SUM(H3:K3) | Q10: =M3*SUM(M3:P3)/SUM(I3:L3) | R10: =N3*SUM(N3:Q3)/SUM(J3:M3) | ... AI10: =AE3*SUM(AE3:AH3)/SUM(AA3:AD3)
A11: H1 backlog APE % | K11: =ABS(K3-K8)/K3*100 | L11: =ABS(L3-L8)/L3*100 | M11: =ABS(M3-M8)/M3*100 | N11: =ABS(N3-N8)/N3*100 | O11: =ABS(O3-O8)/O3*100 | P11: =ABS(P3-P8)/P3*100 | Q11: =ABS(Q3-Q8)/Q3*100 | R11: =ABS(R3-R8)/R3*100 | ... AI11: =ABS(AI3-AI8)/AI3*100
A12: H1 seasonal naive APE % | K12: =ABS(K3-K9)/K3*100 | L12: =ABS(L3-L9)/L3*100 | M12: =ABS(M3-M9)/M3*100 | N12: =ABS(N3-N9)/N3*100 | O12: =ABS(O3-O9)/O3*100 | P12: =ABS(P3-P9)/P3*100 | Q12: =ABS(Q3-Q9)/Q3*100 | R12: =ABS(R3-R9)/R3*100 | ... AI12: =ABS(AI3-AI9)/AI3*100
A13: H1 naive with drift APE % | K13: =ABS(K3-K10)/K3*100 | L13: =ABS(L3-L10)/L3*100 | M13: =ABS(M3-M10)/M3*100 | N13: =ABS(N3-N10)/N3*100 | O13: =ABS(O3-O10)/O3*100 | P13: =ABS(P3-P10)/P3*100 | Q13: =ABS(Q3-Q10)/Q3*100 | R13: =ABS(R3-R10)/R3*100 | ... AI13: =ABS(AI3-AI10)/AI3*100
A14: H4 actual | J14: =SUM(K3:N3) | K14: =SUM(L3:O3) | L14: =SUM(M3:P3) | M14: =SUM(N3:Q3) | N14: =SUM(O3:R3) | O14: =SUM(P3:S3) | P14: =SUM(Q3:T3) | Q14: =SUM(R3:U3) | ... AE14: =SUM(AF3:AI3)
A15: H4 backlog forecast | J15: =J2*AVERAGE(C7:F7) | K15: =K2*AVERAGE(D7:G7) | L15: =L2*AVERAGE(E7:H7) | M15: =M2*AVERAGE(F7:I7) | N15: =N2*AVERAGE(G7:J7) | O15: =O2*AVERAGE(H7:K7) | P15: =P2*AVERAGE(I7:L7) | Q15: =Q2*AVERAGE(J7:M7) | ... AE15: =AE2*AVERAGE(X7:AA7)
A16: H4 trailing 4Q | J16: =SUM(G3:J3) | K16: =SUM(H3:K3) | L16: =SUM(I3:L3) | M16: =SUM(J3:M3) | N16: =SUM(K3:N3) | O16: =SUM(L3:O3) | P16: =SUM(M3:P3) | Q16: =SUM(N3:Q3) | ... AE16: =SUM(AB3:AE3)
A17: H4 trailing 4Q with drift | J17: =SUM(G3:J3)^2/SUM(C3:F3) | K17: =SUM(H3:K3)^2/SUM(D3:G3) | L17: =SUM(I3:L3)^2/SUM(E3:H3) | M17: =SUM(J3:M3)^2/SUM(F3:I3) | N17: =SUM(K3:N3)^2/SUM(G3:J3) | O17: =SUM(L3:O3)^2/SUM(H3:K3) | P17: =SUM(M3:P3)^2/SUM(I3:L3) | Q17: =SUM(N3:Q3)^2/SUM(J3:M3) | ... AE17: =SUM(AB3:AE3)^2/SUM(X3:AA3)
A18: H4 backlog APE % | J18: =ABS(J14-J15)/J14*100 | K18: =ABS(K14-K15)/K14*100 | L18: =ABS(L14-L15)/L14*100 | M18: =ABS(M14-M15)/M14*100 | N18: =ABS(N14-N15)/N14*100 | O18: =ABS(O14-O15)/O14*100 | P18: =ABS(P14-P15)/P14*100 | Q18: =ABS(Q14-Q15)/Q14*100 | ... AE18: =ABS(AE14-AE15)/AE14*100
A19: H4 trailing 4Q APE % | J19: =ABS(J14-J16)/J14*100 | K19: =ABS(K14-K16)/K14*100 | L19: =ABS(L14-L16)/L14*100 | M19: =ABS(M14-M16)/M14*100 | N19: =ABS(N14-N16)/N14*100 | O19: =ABS(O14-O16)/O14*100 | P19: =ABS(P14-P16)/P14*100 | Q19: =ABS(Q14-Q16)/Q14*100 | ... AE19: =ABS(AE14-AE16)/AE14*100
A20: H4 trailing 4Q with drift APE % | J20: =ABS(J14-J17)/J14*100 | K20: =ABS(K14-K17)/K14*100 | L20: =ABS(L14-L17)/L14*100 | M20: =ABS(M14-M17)/M14*100 | N20: =ABS(N14-N17)/N14*100 | O20: =ABS(O14-O17)/O14*100 | P20: =ABS(P14-P17)/P14*100 | Q20: =ABS(Q14-Q17)/Q14*100 | ... AE20: =ABS(AE14-AE17)/AE14*100

Sheet NOC
A1: Quarter | B1: 2018Q3 | C1: 2018Q4 | D1: 2019Q1 | E1: 2019Q2 | F1: 2019Q3 | G1: 2019Q4 | H1: 2020Q1 | I1: 2020Q2 | J1: 2020Q3 | K1: 2020Q4 | L1: 2021Q1 | M1: 2021Q2 | N1: 2021Q3 | O1: 2021Q4 | P1: 2022Q1 | Q1: 2022Q2 | R1: 2022Q3 | S1: 2022Q4 | T1: 2023Q1 | U1: 2023Q2 | V1: 2023Q3 | W1: 2023Q4 | X1: 2024Q1 | Y1: 2024Q2 | Z1: 2024Q3 | AA1: 2024Q4 | AB1: 2025Q1 | AC1: 2025Q2 | AD1: 2025Q3 | AE1: 2025Q4 | AF1: 2026Q1 | AG1: 2026Q2
A2: Backlog (RPO) | B2: 52600 | C2: 53500 | D2: 57300 | E2: 63000 | F2: 65000 | G2: 64800 | H2: 64200 | I2: 70000 | J2: 81300 | K2: 81000 | L2: 79300 | M2: 76600 | N2: 74800 | O2: 76000 | P2: 75800 | Q2: 80000 | R2: 79600 | S2: 78700 | T2: 77500 | U2: 78800 | V2: 83900 | W2: 84200 | X2: 78900 | Y2: 83100 | Z2: 84800 | AA2: 91500 | AB2: 92800 | AC2: 89700 | AD2: 91400 | AE2: 95700 | AF2: 95600 | AG2: 104700
A3: Revenue | B3: 8085 | C3: 8156 | D3: 8189 | E3: 8456 | F3: 8475 | G3: 8721 | H3: 8620 | I3: 8884 | J3: 9083 | K3: 10212 | L3: 9157 | M3: 9151 | N3: 8720 | O3: 8639 | P3: 8797 | Q3: 8801 | R3: 8971 | S3: 10033 | T3: 9301 | U3: 9576 | V3: 9775 | W3: 10638 | X3: 10133 | Y3: 10218 | Z3: 9996 | AA3: 10686 | AB3: 9468 | AC3: 10351 | AD3: 10423 | AE3: 11712 | AF3: 9881 | AG3: 10876
A4: Implied bookings | C4: =C2-B2+C3 | D4: =D2-C2+D3 | E4: =E2-D2+E3 | F4: =F2-E2+F3 | G4: =G2-F2+G3 | H4: =H2-G2+H3 | I4: =I2-H2+I3 | J4: =J2-I2+J3 | ... AG4: =AG2-AF2+AG3
A5: Book-to-bill | C5: =C4/C3 | D5: =D4/D3 | E5: =E4/E3 | F5: =F4/F3 | G5: =G4/G3 | H5: =H4/H3 | I5: =I4/I3 | J5: =J4/J3 | ... AG5: =AG4/AG3
A6: Conversion 1Q | B6: =C3/B2 | C6: =D3/C2 | D6: =E3/D2 | E6: =F3/E2 | F6: =G3/F2 | G6: =H3/G2 | H6: =I3/H2 | I6: =J3/I2 | ... AF6: =AG3/AF2
A7: Conversion 4Q | B7: =SUM(C3:F3)/B2 | C7: =SUM(D3:G3)/C2 | D7: =SUM(E3:H3)/D2 | E7: =SUM(F3:I3)/E2 | F7: =SUM(G3:J3)/F2 | G7: =SUM(H3:K3)/G2 | H7: =SUM(I3:L3)/H2 | I7: =SUM(J3:M3)/I2 | ... AC7: =SUM(AD3:AG3)/AC2
A8: H1 backlog forecast | K8: =J2*AVERAGE(F6,B6) | L8: =K2*AVERAGE(G6,C6) | M8: =L2*AVERAGE(H6,D6) | N8: =M2*AVERAGE(I6,E6) | O8: =N2*AVERAGE(J6,F6) | P8: =O2*AVERAGE(K6,G6) | Q8: =P2*AVERAGE(L6,H6) | R8: =Q2*AVERAGE(M6,I6) | ... AG8: =AF2*AVERAGE(AB6,X6)
A9: H1 seasonal naive | K9: =G3 | L9: =H3 | M9: =I3 | N9: =J3 | O9: =K3 | P9: =L3 | Q9: =M3 | R9: =N3 | ... AG9: =AC3
A10: H1 naive with drift | K10: =G3*SUM(G3:J3)/SUM(C3:F3) | L10: =H3*SUM(H3:K3)/SUM(D3:G3) | M10: =I3*SUM(I3:L3)/SUM(E3:H3) | N10: =J3*SUM(J3:M3)/SUM(F3:I3) | O10: =K3*SUM(K3:N3)/SUM(G3:J3) | P10: =L3*SUM(L3:O3)/SUM(H3:K3) | Q10: =M3*SUM(M3:P3)/SUM(I3:L3) | R10: =N3*SUM(N3:Q3)/SUM(J3:M3) | ... AG10: =AC3*SUM(AC3:AF3)/SUM(Y3:AB3)
A11: H1 backlog APE % | K11: =ABS(K3-K8)/K3*100 | L11: =ABS(L3-L8)/L3*100 | M11: =ABS(M3-M8)/M3*100 | N11: =ABS(N3-N8)/N3*100 | O11: =ABS(O3-O8)/O3*100 | P11: =ABS(P3-P8)/P3*100 | Q11: =ABS(Q3-Q8)/Q3*100 | R11: =ABS(R3-R8)/R3*100 | ... AG11: =ABS(AG3-AG8)/AG3*100
A12: H1 seasonal naive APE % | K12: =ABS(K3-K9)/K3*100 | L12: =ABS(L3-L9)/L3*100 | M12: =ABS(M3-M9)/M3*100 | N12: =ABS(N3-N9)/N3*100 | O12: =ABS(O3-O9)/O3*100 | P12: =ABS(P3-P9)/P3*100 | Q12: =ABS(Q3-Q9)/Q3*100 | R12: =ABS(R3-R9)/R3*100 | ... AG12: =ABS(AG3-AG9)/AG3*100
A13: H1 naive with drift APE % | K13: =ABS(K3-K10)/K3*100 | L13: =ABS(L3-L10)/L3*100 | M13: =ABS(M3-M10)/M3*100 | N13: =ABS(N3-N10)/N3*100 | O13: =ABS(O3-O10)/O3*100 | P13: =ABS(P3-P10)/P3*100 | Q13: =ABS(Q3-Q10)/Q3*100 | R13: =ABS(R3-R10)/R3*100 | ... AG13: =ABS(AG3-AG10)/AG3*100
A14: H4 actual | J14: =SUM(K3:N3) | K14: =SUM(L3:O3) | L14: =SUM(M3:P3) | M14: =SUM(N3:Q3) | N14: =SUM(O3:R3) | O14: =SUM(P3:S3) | P14: =SUM(Q3:T3) | Q14: =SUM(R3:U3) | ... AC14: =SUM(AD3:AG3)
A15: H4 backlog forecast | J15: =J2*AVERAGE(C7:F7) | K15: =K2*AVERAGE(D7:G7) | L15: =L2*AVERAGE(E7:H7) | M15: =M2*AVERAGE(F7:I7) | N15: =N2*AVERAGE(G7:J7) | O15: =O2*AVERAGE(H7:K7) | P15: =P2*AVERAGE(I7:L7) | Q15: =Q2*AVERAGE(J7:M7) | ... AC15: =AC2*AVERAGE(V7:Y7)
A16: H4 trailing 4Q | J16: =SUM(G3:J3) | K16: =SUM(H3:K3) | L16: =SUM(I3:L3) | M16: =SUM(J3:M3) | N16: =SUM(K3:N3) | O16: =SUM(L3:O3) | P16: =SUM(M3:P3) | Q16: =SUM(N3:Q3) | ... AC16: =SUM(Z3:AC3)
A17: H4 trailing 4Q with drift | J17: =SUM(G3:J3)^2/SUM(C3:F3) | K17: =SUM(H3:K3)^2/SUM(D3:G3) | L17: =SUM(I3:L3)^2/SUM(E3:H3) | M17: =SUM(J3:M3)^2/SUM(F3:I3) | N17: =SUM(K3:N3)^2/SUM(G3:J3) | O17: =SUM(L3:O3)^2/SUM(H3:K3) | P17: =SUM(M3:P3)^2/SUM(I3:L3) | Q17: =SUM(N3:Q3)^2/SUM(J3:M3) | ... AC17: =SUM(Z3:AC3)^2/SUM(V3:Y3)
A18: H4 backlog APE % | J18: =ABS(J14-J15)/J14*100 | K18: =ABS(K14-K15)/K14*100 | L18: =ABS(L14-L15)/L14*100 | M18: =ABS(M14-M15)/M14*100 | N18: =ABS(N14-N15)/N14*100 | O18: =ABS(O14-O15)/O14*100 | P18: =ABS(P14-P15)/P14*100 | Q18: =ABS(Q14-Q15)/Q14*100 | ... AC18: =ABS(AC14-AC15)/AC14*100
A19: H4 trailing 4Q APE % | J19: =ABS(J14-J16)/J14*100 | K19: =ABS(K14-K16)/K14*100 | L19: =ABS(L14-L16)/L14*100 | M19: =ABS(M14-M16)/M14*100 | N19: =ABS(N14-N16)/N14*100 | O19: =ABS(O14-O16)/O14*100 | P19: =ABS(P14-P16)/P14*100 | Q19: =ABS(Q14-Q16)/Q14*100 | ... AC19: =ABS(AC14-AC16)/AC14*100
A20: H4 trailing 4Q with drift APE % | J20: =ABS(J14-J17)/J14*100 | K20: =ABS(K14-K17)/K14*100 | L20: =ABS(L14-L17)/L14*100 | M20: =ABS(M14-M17)/M14*100 | N20: =ABS(N14-N17)/N14*100 | O20: =ABS(O14-O17)/O14*100 | P20: =ABS(P14-P17)/P14*100 | Q20: =ABS(Q14-Q17)/Q14*100 | ... AC20: =ABS(AC14-AC17)/AC14*100

Sheet RTX
A1: Quarter | B1: 2020Q2 | C1: 2020Q3 | D1: 2020Q4 | E1: 2021Q1 | F1: 2021Q2 | G1: 2021Q3 | H1: 2021Q4 | I1: 2022Q1 | J1: 2022Q2 | K1: 2022Q3 | L1: 2022Q4 | M1: 2023Q1 | N1: 2023Q2 | O1: 2023Q3 | P1: 2023Q4 | Q1: 2024Q1 | R1: 2024Q2 | S1: 2024Q3 | T1: 2024Q4 | U1: 2025Q1 | V1: 2025Q2 | W1: 2025Q3 | X1: 2025Q4 | Y1: 2026Q1 | Z1: 2026Q2
A2: Backlog (RPO) | B2: 158700 | C2: 152300 | D2: 150100 | E2: 147400 | F2: 151800 | G2: 156100 | H2: 156000 | I2: 154000 | J2: 161000 | K2: 168000 | L2: 175000 | M2: 180000 | N2: 185000 | O2: 190000 | P2: 196000 | Q2: 202000 | R2: 206000 | S2: 221000 | T2: 218000 | U2: 217000 | V2: 236000 | W2: 251000 | X2: 268000 | Y2: 271000 | Z2: 289000
A3: Revenue | B3: 14061 | C3: 14747 | D3: 16419 | E3: 15251 | F3: 15880 | G3: 16213 | H3: 17044 | I3: 15716 | J3: 16314 | K3: 16951 | L3: 18093 | M3: 17214 | N3: 18315 | O3: 13464 | P3: 19927 | Q3: 19305 | R3: 19721 | S3: 20089 | T3: 21623 | U3: 20306 | V3: 21581 | W3: 22478 | X3: 24238 | Y3: 22076 | Z3: 24708
A4: Implied bookings | C4: =C2-B2+C3 | D4: =D2-C2+D3 | E4: =E2-D2+E3 | F4: =F2-E2+F3 | G4: =G2-F2+G3 | H4: =H2-G2+H3 | I4: =I2-H2+I3 | J4: =J2-I2+J3 | ... Z4: =Z2-Y2+Z3
A5: Book-to-bill | C5: =C4/C3 | D5: =D4/D3 | E5: =E4/E3 | F5: =F4/F3 | G5: =G4/G3 | H5: =H4/H3 | I5: =I4/I3 | J5: =J4/J3 | ... Z5: =Z4/Z3
A6: Conversion 1Q | B6: =C3/B2 | C6: =D3/C2 | D6: =E3/D2 | E6: =F3/E2 | F6: =G3/F2 | G6: =H3/G2 | H6: =I3/H2 | I6: =J3/I2 | ... Y6: =Z3/Y2
A7: Conversion 4Q | B7: =SUM(C3:F3)/B2 | C7: =SUM(D3:G3)/C2 | D7: =SUM(E3:H3)/D2 | E7: =SUM(F3:I3)/E2 | F7: =SUM(G3:J3)/F2 | G7: =SUM(H3:K3)/G2 | H7: =SUM(I3:L3)/H2 | I7: =SUM(J3:M3)/I2 | ... V7: =SUM(W3:Z3)/V2
A8: H1 backlog forecast | K8: =J2*AVERAGE(F6,B6) | L8: =K2*AVERAGE(G6,C6) | M8: =L2*AVERAGE(H6,D6) | N8: =M2*AVERAGE(I6,E6) | O8: =N2*AVERAGE(J6,F6) | P8: =O2*AVERAGE(K6,G6) | Q8: =P2*AVERAGE(L6,H6) | R8: =Q2*AVERAGE(M6,I6) | ... Z8: =Y2*AVERAGE(U6,Q6)
A9: H1 seasonal naive | K9: =G3 | L9: =H3 | M9: =I3 | N9: =J3 | O9: =K3 | P9: =L3 | Q9: =M3 | R9: =N3 | ... Z9: =V3
A10: H1 naive with drift | K10: =G3*SUM(G3:J3)/SUM(C3:F3) | L10: =H3*SUM(H3:K3)/SUM(D3:G3) | M10: =I3*SUM(I3:L3)/SUM(E3:H3) | N10: =J3*SUM(J3:M3)/SUM(F3:I3) | O10: =K3*SUM(K3:N3)/SUM(G3:J3) | P10: =L3*SUM(L3:O3)/SUM(H3:K3) | Q10: =M3*SUM(M3:P3)/SUM(I3:L3) | R10: =N3*SUM(N3:Q3)/SUM(J3:M3) | ... Z10: =V3*SUM(V3:Y3)/SUM(R3:U3)
A11: H1 backlog APE % | K11: =ABS(K3-K8)/K3*100 | L11: =ABS(L3-L8)/L3*100 | M11: =ABS(M3-M8)/M3*100 | N11: =ABS(N3-N8)/N3*100 | O11: =ABS(O3-O8)/O3*100 | P11: =ABS(P3-P8)/P3*100 | Q11: =ABS(Q3-Q8)/Q3*100 | R11: =ABS(R3-R8)/R3*100 | ... Z11: =ABS(Z3-Z8)/Z3*100
A12: H1 seasonal naive APE % | K12: =ABS(K3-K9)/K3*100 | L12: =ABS(L3-L9)/L3*100 | M12: =ABS(M3-M9)/M3*100 | N12: =ABS(N3-N9)/N3*100 | O12: =ABS(O3-O9)/O3*100 | P12: =ABS(P3-P9)/P3*100 | Q12: =ABS(Q3-Q9)/Q3*100 | R12: =ABS(R3-R9)/R3*100 | ... Z12: =ABS(Z3-Z9)/Z3*100
A13: H1 naive with drift APE % | K13: =ABS(K3-K10)/K3*100 | L13: =ABS(L3-L10)/L3*100 | M13: =ABS(M3-M10)/M3*100 | N13: =ABS(N3-N10)/N3*100 | O13: =ABS(O3-O10)/O3*100 | P13: =ABS(P3-P10)/P3*100 | Q13: =ABS(Q3-Q10)/Q3*100 | R13: =ABS(R3-R10)/R3*100 | ... Z13: =ABS(Z3-Z10)/Z3*100
A14: H4 actual | J14: =SUM(K3:N3) | K14: =SUM(L3:O3) | L14: =SUM(M3:P3) | M14: =SUM(N3:Q3) | N14: =SUM(O3:R3) | O14: =SUM(P3:S3) | P14: =SUM(Q3:T3) | Q14: =SUM(R3:U3) | ... V14: =SUM(W3:Z3)
A15: H4 backlog forecast | J15: =J2*AVERAGE(C7:F7) | K15: =K2*AVERAGE(D7:G7) | L15: =L2*AVERAGE(E7:H7) | M15: =M2*AVERAGE(F7:I7) | N15: =N2*AVERAGE(G7:J7) | O15: =O2*AVERAGE(H7:K7) | P15: =P2*AVERAGE(I7:L7) | Q15: =Q2*AVERAGE(J7:M7) | ... V15: =V2*AVERAGE(O7:R7)
A16: H4 trailing 4Q | J16: =SUM(G3:J3) | K16: =SUM(H3:K3) | L16: =SUM(I3:L3) | M16: =SUM(J3:M3) | N16: =SUM(K3:N3) | O16: =SUM(L3:O3) | P16: =SUM(M3:P3) | Q16: =SUM(N3:Q3) | ... V16: =SUM(S3:V3)
A17: H4 trailing 4Q with drift | J17: =SUM(G3:J3)^2/SUM(C3:F3) | K17: =SUM(H3:K3)^2/SUM(D3:G3) | L17: =SUM(I3:L3)^2/SUM(E3:H3) | M17: =SUM(J3:M3)^2/SUM(F3:I3) | N17: =SUM(K3:N3)^2/SUM(G3:J3) | O17: =SUM(L3:O3)^2/SUM(H3:K3) | P17: =SUM(M3:P3)^2/SUM(I3:L3) | Q17: =SUM(N3:Q3)^2/SUM(J3:M3) | ... V17: =SUM(S3:V3)^2/SUM(O3:R3)
A18: H4 backlog APE % | J18: =ABS(J14-J15)/J14*100 | K18: =ABS(K14-K15)/K14*100 | L18: =ABS(L14-L15)/L14*100 | M18: =ABS(M14-M15)/M14*100 | N18: =ABS(N14-N15)/N14*100 | O18: =ABS(O14-O15)/O14*100 | P18: =ABS(P14-P15)/P14*100 | Q18: =ABS(Q14-Q15)/Q14*100 | ... V18: =ABS(V14-V15)/V14*100
A19: H4 trailing 4Q APE % | J19: =ABS(J14-J16)/J14*100 | K19: =ABS(K14-K16)/K14*100 | L19: =ABS(L14-L16)/L14*100 | M19: =ABS(M14-M16)/M14*100 | N19: =ABS(N14-N16)/N14*100 | O19: =ABS(O14-O16)/O14*100 | P19: =ABS(P14-P16)/P14*100 | Q19: =ABS(Q14-Q16)/Q14*100 | ... V19: =ABS(V14-V16)/V14*100
A20: H4 trailing 4Q with drift APE % | J20: =ABS(J14-J17)/J14*100 | K20: =ABS(K14-K17)/K14*100 | L20: =ABS(L14-L17)/L14*100 | M20: =ABS(M14-M17)/M14*100 | N20: =ABS(N14-N17)/N14*100 | O20: =ABS(O14-O17)/O14*100 | P20: =ABS(P14-P17)/P14*100 | Q20: =ABS(Q14-Q17)/Q14*100 | ... V20: =ABS(V14-V17)/V14*100

Sheet Bridge
A1: Ticker | B1: Year | C1: Revenue prior | D1: Revenue | E1: Backlog start prior | F1: Backlog start | G1: Conversion prior | H1: Conversion | I1: Backlog effect | J1: Conversion effect | K1: Interaction | L1: Residual
A2: HII | B2: 2020 | C2: =SUM(HII!F3:I3) | D2: =SUM(HII!J3:M3) | E2: =HII!E2 | F2: =HII!I2 | G2: =C2/E2 | H2: =D2/F2 | I2: =(F2-E2)*G2 | J2: =E2*(H2-G2) | K2: =(F2-E2)*(H2-G2) | L2: =(D2-C2)-(I2+J2+K2)
A3: HII | B3: 2021 | C3: =SUM(HII!J3:M3) | D3: =SUM(HII!N3:Q3) | E3: =HII!I2 | F3: =HII!M2 | G3: =C3/E3 | H3: =D3/F3 | I3: =(F3-E3)*G3 | J3: =E3*(H3-G3) | K3: =(F3-E3)*(H3-G3) | L3: =(D3-C3)-(I3+J3+K3)
A4: HII | B4: 2022 | C4: =SUM(HII!N3:Q3) | D4: =SUM(HII!R3:U3) | E4: =HII!M2 | F4: =HII!Q2 | G4: =C4/E4 | H4: =D4/F4 | I4: =(F4-E4)*G4 | J4: =E4*(H4-G4) | K4: =(F4-E4)*(H4-G4) | L4: =(D4-C4)-(I4+J4+K4)
A5: HII | B5: 2023 | C5: =SUM(HII!R3:U3) | D5: =SUM(HII!V3:Y3) | E5: =HII!Q2 | F5: =HII!U2 | G5: =C5/E5 | H5: =D5/F5 | I5: =(F5-E5)*G5 | J5: =E5*(H5-G5) | K5: =(F5-E5)*(H5-G5) | L5: =(D5-C5)-(I5+J5+K5)
A6: HII | B6: 2024 | C6: =SUM(HII!V3:Y3) | D6: =SUM(HII!Z3:AC3) | E6: =HII!U2 | F6: =HII!Y2 | G6: =C6/E6 | H6: =D6/F6 | I6: =(F6-E6)*G6 | J6: =E6*(H6-G6) | K6: =(F6-E6)*(H6-G6) | L6: =(D6-C6)-(I6+J6+K6)
A7: HII | B7: 2025 | C7: =SUM(HII!Z3:AC3) | D7: =SUM(HII!AD3:AG3) | E7: =HII!Y2 | F7: =HII!AC2 | G7: =C7/E7 | H7: =D7/F7 | I7: =(F7-E7)*G7 | J7: =E7*(H7-G7) | K7: =(F7-E7)*(H7-G7) | L7: =(D7-C7)-(I7+J7+K7)
A8: LHX | B8: 2022 | C8: =SUM(LHX!F3:I3) | D8: =SUM(LHX!J3:M3) | E8: =LHX!E2 | F8: =LHX!I2 | G8: =C8/E8 | H8: =D8/F8 | I8: =(F8-E8)*G8 | J8: =E8*(H8-G8) | K8: =(F8-E8)*(H8-G8) | L8: =(D8-C8)-(I8+J8+K8)
A9: LHX | B9: 2023 | C9: =SUM(LHX!J3:M3) | D9: =SUM(LHX!N3:Q3) | E9: =LHX!I2 | F9: =LHX!M2 | G9: =C9/E9 | H9: =D9/F9 | I9: =(F9-E9)*G9 | J9: =E9*(H9-G9) | K9: =(F9-E9)*(H9-G9) | L9: =(D9-C9)-(I9+J9+K9)
A10: LHX | B10: 2024 | C10: =SUM(LHX!N3:Q3) | D10: =SUM(LHX!R3:U3) | E10: =LHX!M2 | F10: =LHX!Q2 | G10: =C10/E10 | H10: =D10/F10 | I10: =(F10-E10)*G10 | J10: =E10*(H10-G10) | K10: =(F10-E10)*(H10-G10) | L10: =(D10-C10)-(I10+J10+K10)
A11: LHX | B11: 2025 | C11: =SUM(LHX!R3:U3) | D11: =SUM(LHX!V3:Y3) | E11: =LHX!Q2 | F11: =LHX!U2 | G11: =C11/E11 | H11: =D11/F11 | I11: =(F11-E11)*G11 | J11: =E11*(H11-G11) | K11: =(F11-E11)*(H11-G11) | L11: =(D11-C11)-(I11+J11+K11)
A12: LMT | B12: 2020 | C12: =SUM(LMT!F3:I3) | D12: =SUM(LMT!J3:M3) | E12: =LMT!E2 | F12: =LMT!I2 | G12: =C12/E12 | H12: =D12/F12 | I12: =(F12-E12)*G12 | J12: =E12*(H12-G12) | K12: =(F12-E12)*(H12-G12) | L12: =(D12-C12)-(I12+J12+K12)
A13: LMT | B13: 2021 | C13: =SUM(LMT!J3:M3) | D13: =SUM(LMT!N3:Q3) | E13: =LMT!I2 | F13: =LMT!M2 | G13: =C13/E13 | H13: =D13/F13 | I13: =(F13-E13)*G13 | J13: =E13*(H13-G13) | K13: =(F13-E13)*(H13-G13) | L13: =(D13-C13)-(I13+J13+K13)
A14: LMT | B14: 2022 | C14: =SUM(LMT!N3:Q3) | D14: =SUM(LMT!R3:U3) | E14: =LMT!M2 | F14: =LMT!Q2 | G14: =C14/E14 | H14: =D14/F14 | I14: =(F14-E14)*G14 | J14: =E14*(H14-G14) | K14: =(F14-E14)*(H14-G14) | L14: =(D14-C14)-(I14+J14+K14)
A15: LMT | B15: 2023 | C15: =SUM(LMT!R3:U3) | D15: =SUM(LMT!V3:Y3) | E15: =LMT!Q2 | F15: =LMT!U2 | G15: =C15/E15 | H15: =D15/F15 | I15: =(F15-E15)*G15 | J15: =E15*(H15-G15) | K15: =(F15-E15)*(H15-G15) | L15: =(D15-C15)-(I15+J15+K15)
A16: LMT | B16: 2024 | C16: =SUM(LMT!V3:Y3) | D16: =SUM(LMT!Z3:AC3) | E16: =LMT!U2 | F16: =LMT!Y2 | G16: =C16/E16 | H16: =D16/F16 | I16: =(F16-E16)*G16 | J16: =E16*(H16-G16) | K16: =(F16-E16)*(H16-G16) | L16: =(D16-C16)-(I16+J16+K16)
A17: LMT | B17: 2025 | C17: =SUM(LMT!Z3:AC3) | D17: =SUM(LMT!AD3:AG3) | E17: =LMT!Y2 | F17: =LMT!AC2 | G17: =C17/E17 | H17: =D17/F17 | I17: =(F17-E17)*G17 | J17: =E17*(H17-G17) | K17: =(F17-E17)*(H17-G17) | L17: =(D17-C17)-(I17+J17+K17)
A18: NOC | B18: 2020 | C18: =SUM(NOC!D3:G3) | D18: =SUM(NOC!H3:K3) | E18: =NOC!C2 | F18: =NOC!G2 | G18: =C18/E18 | H18: =D18/F18 | I18: =(F18-E18)*G18 | J18: =E18*(H18-G18) | K18: =(F18-E18)*(H18-G18) | L18: =(D18-C18)-(I18+J18+K18)
A19: NOC | B19: 2021 | C19: =SUM(NOC!H3:K3) | D19: =SUM(NOC!L3:O3) | E19: =NOC!G2 | F19: =NOC!K2 | G19: =C19/E19 | H19: =D19/F19 | I19: =(F19-E19)*G19 | J19: =E19*(H19-G19) | K19: =(F19-E19)*(H19-G19) | L19: =(D19-C19)-(I19+J19+K19)
A20: NOC | B20: 2022 | C20: =SUM(NOC!L3:O3) | D20: =SUM(NOC!P3:S3) | E20: =NOC!K2 | F20: =NOC!O2 | G20: =C20/E20 | H20: =D20/F20 | I20: =(F20-E20)*G20 | J20: =E20*(H20-G20) | K20: =(F20-E20)*(H20-G20) | L20: =(D20-C20)-(I20+J20+K20)
A21: NOC | B21: 2023 | C21: =SUM(NOC!P3:S3) | D21: =SUM(NOC!T3:W3) | E21: =NOC!O2 | F21: =NOC!S2 | G21: =C21/E21 | H21: =D21/F21 | I21: =(F21-E21)*G21 | J21: =E21*(H21-G21) | K21: =(F21-E21)*(H21-G21) | L21: =(D21-C21)-(I21+J21+K21)
A22: NOC | B22: 2024 | C22: =SUM(NOC!T3:W3) | D22: =SUM(NOC!X3:AA3) | E22: =NOC!S2 | F22: =NOC!W2 | G22: =C22/E22 | H22: =D22/F22 | I22: =(F22-E22)*G22 | J22: =E22*(H22-G22) | K22: =(F22-E22)*(H22-G22) | L22: =(D22-C22)-(I22+J22+K22)
A23: NOC | B23: 2025 | C23: =SUM(NOC!X3:AA3) | D23: =SUM(NOC!AB3:AE3) | E23: =NOC!W2 | F23: =NOC!AA2 | G23: =C23/E23 | H23: =D23/F23 | I23: =(F23-E23)*G23 | J23: =E23*(H23-G23) | K23: =(F23-E23)*(H23-G23) | L23: =(D23-C23)-(I23+J23+K23)
A24: RTX | B24: 2022 | C24: =SUM(RTX!E3:H3) | D24: =SUM(RTX!I3:L3) | E24: =RTX!D2 | F24: =RTX!H2 | G24: =C24/E24 | H24: =D24/F24 | I24: =(F24-E24)*G24 | J24: =E24*(H24-G24) | K24: =(F24-E24)*(H24-G24) | L24: =(D24-C24)-(I24+J24+K24)
A25: RTX | B25: 2023 | C25: =SUM(RTX!I3:L3) | D25: =SUM(RTX!M3:P3) | E25: =RTX!H2 | F25: =RTX!L2 | G25: =C25/E25 | H25: =D25/F25 | I25: =(F25-E25)*G25 | J25: =E25*(H25-G25) | K25: =(F25-E25)*(H25-G25) | L25: =(D25-C25)-(I25+J25+K25)
A26: RTX | B26: 2024 | C26: =SUM(RTX!M3:P3) | D26: =SUM(RTX!Q3:T3) | E26: =RTX!L2 | F26: =RTX!P2 | G26: =C26/E26 | H26: =D26/F26 | I26: =(F26-E26)*G26 | J26: =E26*(H26-G26) | K26: =(F26-E26)*(H26-G26) | L26: =(D26-C26)-(I26+J26+K26)
A27: RTX | B27: 2025 | C27: =SUM(RTX!Q3:T3) | D27: =SUM(RTX!U3:X3) | E27: =RTX!P2 | F27: =RTX!T2 | G27: =C27/E27 | H27: =D27/F27 | I27: =(F27-E27)*G27 | J27: =E27*(H27-G27) | K27: =(F27-E27)*(H27-G27) | L27: =(D27-C27)-(I27+J27+K27)

Sheet Sensitivity
A1: Ticker | B1: Backlog shock % | C1: Conversion shift pp | D1: Forward revenue
A2: HII | B2: -10 | C2: -3 | D2: =HII!AI2*(1+B2/100)*(AVERAGE(HII!AB7:AE7)+C2/100)
A3: HII | B3: -10 | C3: -1.5 | D3: =HII!AI2*(1+B3/100)*(AVERAGE(HII!AB7:AE7)+C3/100)
A4: HII | B4: -10 | C4: 0 | D4: =HII!AI2*(1+B4/100)*(AVERAGE(HII!AB7:AE7)+C4/100)
A5: HII | B5: -10 | C5: 1.5 | D5: =HII!AI2*(1+B5/100)*(AVERAGE(HII!AB7:AE7)+C5/100)
A6: HII | B6: -10 | C6: 3 | D6: =HII!AI2*(1+B6/100)*(AVERAGE(HII!AB7:AE7)+C6/100)
A7: HII | B7: -5 | C7: -3 | D7: =HII!AI2*(1+B7/100)*(AVERAGE(HII!AB7:AE7)+C7/100)
A8: HII | B8: -5 | C8: -1.5 | D8: =HII!AI2*(1+B8/100)*(AVERAGE(HII!AB7:AE7)+C8/100)
A9: HII | B9: -5 | C9: 0 | D9: =HII!AI2*(1+B9/100)*(AVERAGE(HII!AB7:AE7)+C9/100)
A10: HII | B10: -5 | C10: 1.5 | D10: =HII!AI2*(1+B10/100)*(AVERAGE(HII!AB7:AE7)+C10/100)
A11: HII | B11: -5 | C11: 3 | D11: =HII!AI2*(1+B11/100)*(AVERAGE(HII!AB7:AE7)+C11/100)
A12: HII | B12: 0 | C12: -3 | D12: =HII!AI2*(1+B12/100)*(AVERAGE(HII!AB7:AE7)+C12/100)
A13: HII | B13: 0 | C13: -1.5 | D13: =HII!AI2*(1+B13/100)*(AVERAGE(HII!AB7:AE7)+C13/100)
A14: HII | B14: 0 | C14: 0 | D14: =HII!AI2*(1+B14/100)*(AVERAGE(HII!AB7:AE7)+C14/100)
A15: HII | B15: 0 | C15: 1.5 | D15: =HII!AI2*(1+B15/100)*(AVERAGE(HII!AB7:AE7)+C15/100)
A16: HII | B16: 0 | C16: 3 | D16: =HII!AI2*(1+B16/100)*(AVERAGE(HII!AB7:AE7)+C16/100)
A17: HII | B17: 5 | C17: -3 | D17: =HII!AI2*(1+B17/100)*(AVERAGE(HII!AB7:AE7)+C17/100)
A18: HII | B18: 5 | C18: -1.5 | D18: =HII!AI2*(1+B18/100)*(AVERAGE(HII!AB7:AE7)+C18/100)
A19: HII | B19: 5 | C19: 0 | D19: =HII!AI2*(1+B19/100)*(AVERAGE(HII!AB7:AE7)+C19/100)
A20: HII | B20: 5 | C20: 1.5 | D20: =HII!AI2*(1+B20/100)*(AVERAGE(HII!AB7:AE7)+C20/100)
A21: HII | B21: 5 | C21: 3 | D21: =HII!AI2*(1+B21/100)*(AVERAGE(HII!AB7:AE7)+C21/100)
A22: HII | B22: 10 | C22: -3 | D22: =HII!AI2*(1+B22/100)*(AVERAGE(HII!AB7:AE7)+C22/100)
A23: HII | B23: 10 | C23: -1.5 | D23: =HII!AI2*(1+B23/100)*(AVERAGE(HII!AB7:AE7)+C23/100)
A24: HII | B24: 10 | C24: 0 | D24: =HII!AI2*(1+B24/100)*(AVERAGE(HII!AB7:AE7)+C24/100)
A25: HII | B25: 10 | C25: 1.5 | D25: =HII!AI2*(1+B25/100)*(AVERAGE(HII!AB7:AE7)+C25/100)
A26: HII | B26: 10 | C26: 3 | D26: =HII!AI2*(1+B26/100)*(AVERAGE(HII!AB7:AE7)+C26/100)
A27: LHX | B27: -10 | C27: -3 | D27: =LHX!AA2*(1+B27/100)*(AVERAGE(LHX!T7:W7)+C27/100)
A28: LHX | B28: -10 | C28: -1.5 | D28: =LHX!AA2*(1+B28/100)*(AVERAGE(LHX!T7:W7)+C28/100)
A29: LHX | B29: -10 | C29: 0 | D29: =LHX!AA2*(1+B29/100)*(AVERAGE(LHX!T7:W7)+C29/100)
A30: LHX | B30: -10 | C30: 1.5 | D30: =LHX!AA2*(1+B30/100)*(AVERAGE(LHX!T7:W7)+C30/100)
A31: LHX | B31: -10 | C31: 3 | D31: =LHX!AA2*(1+B31/100)*(AVERAGE(LHX!T7:W7)+C31/100)
A32: LHX | B32: -5 | C32: -3 | D32: =LHX!AA2*(1+B32/100)*(AVERAGE(LHX!T7:W7)+C32/100)
A33: LHX | B33: -5 | C33: -1.5 | D33: =LHX!AA2*(1+B33/100)*(AVERAGE(LHX!T7:W7)+C33/100)
A34: LHX | B34: -5 | C34: 0 | D34: =LHX!AA2*(1+B34/100)*(AVERAGE(LHX!T7:W7)+C34/100)
A35: LHX | B35: -5 | C35: 1.5 | D35: =LHX!AA2*(1+B35/100)*(AVERAGE(LHX!T7:W7)+C35/100)
A36: LHX | B36: -5 | C36: 3 | D36: =LHX!AA2*(1+B36/100)*(AVERAGE(LHX!T7:W7)+C36/100)
A37: LHX | B37: 0 | C37: -3 | D37: =LHX!AA2*(1+B37/100)*(AVERAGE(LHX!T7:W7)+C37/100)
A38: LHX | B38: 0 | C38: -1.5 | D38: =LHX!AA2*(1+B38/100)*(AVERAGE(LHX!T7:W7)+C38/100)
A39: LHX | B39: 0 | C39: 0 | D39: =LHX!AA2*(1+B39/100)*(AVERAGE(LHX!T7:W7)+C39/100)
A40: LHX | B40: 0 | C40: 1.5 | D40: =LHX!AA2*(1+B40/100)*(AVERAGE(LHX!T7:W7)+C40/100)
...

Sheet Summary
A1: Metric | B1: ALL | C1: HII | D1: LHX | E1: LMT | F1: NOC | G1: RTX
A2: MAPE H1 backlog | B2: =AVERAGE(HII!B11:AI11,LHX!B11:AA11,LMT!B11:AI11,NOC!B11:AG11,RTX!B11:Z11) | C2: =AVERAGE(HII!B11:AI11) | D2: =AVERAGE(LHX!B11:AA11) | E2: =AVERAGE(LMT!B11:AI11) | F2: =AVERAGE(NOC!B11:AG11) | G2: =AVERAGE(RTX!B11:Z11)
A3: MAPE H1 seasonal naive | B3: =AVERAGE(HII!B12:AI12,LHX!B12:AA12,LMT!B12:AI12,NOC!B12:AG12,RTX!B12:Z12) | C3: =AVERAGE(HII!B12:AI12) | D3: =AVERAGE(LHX!B12:AA12) | E3: =AVERAGE(LMT!B12:AI12) | F3: =AVERAGE(NOC!B12:AG12) | G3: =AVERAGE(RTX!B12:Z12)
A4: MAPE H1 naive with drift | B4: =AVERAGE(HII!B13:AI13,LHX!B13:AA13,LMT!B13:AI13,NOC!B13:AG13,RTX!B13:Z13) | C4: =AVERAGE(HII!B13:AI13) | D4: =AVERAGE(LHX!B13:AA13) | E4: =AVERAGE(LMT!B13:AI13) | F4: =AVERAGE(NOC!B13:AG13) | G4: =AVERAGE(RTX!B13:Z13)
A5: MAPE H4 backlog | B5: =AVERAGE(HII!B18:AI18,LHX!B18:AA18,LMT!B18:AI18,NOC!B18:AG18,RTX!B18:Z18) | C5: =AVERAGE(HII!B18:AI18) | D5: =AVERAGE(LHX!B18:AA18) | E5: =AVERAGE(LMT!B18:AI18) | F5: =AVERAGE(NOC!B18:AG18) | G5: =AVERAGE(RTX!B18:Z18)
A6: MAPE H4 trailing 4Q | B6: =AVERAGE(HII!B19:AI19,LHX!B19:AA19,LMT!B19:AI19,NOC!B19:AG19,RTX!B19:Z19) | C6: =AVERAGE(HII!B19:AI19) | D6: =AVERAGE(LHX!B19:AA19) | E6: =AVERAGE(LMT!B19:AI19) | F6: =AVERAGE(NOC!B19:AG19) | G6: =AVERAGE(RTX!B19:Z19)
A7: MAPE H4 trailing 4Q with drift | B7: =AVERAGE(HII!B20:AI20,LHX!B20:AA20,LMT!B20:AI20,NOC!B20:AG20,RTX!B20:Z20) | C7: =AVERAGE(HII!B20:AI20) | D7: =AVERAGE(LHX!B20:AA20) | E7: =AVERAGE(LMT!B20:AI20) | F7: =AVERAGE(NOC!B20:AG20) | G7: =AVERAGE(RTX!B20:Z20)
